export let Asyncerror = (theFunc) => (req, res, next) => {
    Promise.resolve(theFunc(req, res, next)).catch(next);
        
    
  };